Workbook

Sheet CMDB_servers_operational
A1: Name | B1: Application Relationship | C1: Support Group | D1: Operational status | E1: Most recent discovery | F1: Duplicate Of | G1: Fully qualified domain name | H1: Operating System | I1: Environment | J1: Sub-Environment | K1: Application Relationship | L1: IP Address | M1: DNS Domain | N1: Domain | O1: OS Version
A2: eac2sqbapl10v | B2: SonarQube-CVS | C2: =VLOOKUP(B2,CMDB_Apps!B:J,9,FALSE) -> DevOps Engineering | D2: Operational | E2: 46070.147 | G2: eac2sqbapl10v.corp.cvscaremark.com | H2: Linux Red Hat | I2: PROD | J2: PROD | K2: SonarQube-CVS | L2: 10.223.153.21 | M2: corp.cvscaremark.com | N2: global | O2: 7.9
A3: rac2ctrapl10v | B3: RXDW IDW | C3: =VLOOKUP(B3,CMDB_Apps!B:J,9,FALSE) -> PS RX DATA WAREHOUSE IDW RDL | D3: Operational | E3: 46070.147 | G3: rac2ctrapl10v.corp.cvscaremark.com | H3: Linux Red Hat | I3: PROD | J3: PROD | K3: RXDW IDW | L3: 10.223.153.13 | M3: corp.cvscaremark.com | N3: global | O3: 7.9
A4: rac2ctradl10v | B4: RXDW IDW | C4: =VLOOKUP(B4,CMDB_Apps!B:J,9,FALSE) -> PS RX DATA WAREHOUSE IDW RDL | D4: Operational | E4: 46070.146 | G4: rac2ctradl10v.corp.cvscaremark.com | H4: Linux Red Hat | I4: DEV | J4: Development | K4: RXDW IDW | L4: 10.223.185.12 | M4: corp.cvscaremark.com | N4: global | O4: 7.9
A5: rac2ctraql10v | B5: RXDW IDW | C5: =VLOOKUP(B5,CMDB_Apps!B:J,9,FALSE) -> PS RX DATA WAREHOUSE IDW RDL | D5: Operational | E5: 46070.146 | G5: rac2ctraql10v.corp.cvscaremark.com | H5: Linux Red Hat | I5: TEST | J5: UAT | K5: RXDW IDW | L5: 10.223.185.14 | M5: corp.cvscaremark.com | N5: global | O5: 7.9
A6: pac4cdiwpl10v | B6: Document Indexing Application | C6: =VLOOKUP(B6,CMDB_Apps!B:J,9,FALSE) -> CORAM-DIA | D6: Operational | E6: 46070.146 | G6: pac4cdiwpl10v.corp.cvscaremark.com | H6: Linux Red Hat | I6: PROD | J6: PROD | K6: Document Indexing Application | L6: 10.223.66.166 | M6: corp.cvscaremark.com | N6: global | O6: 8.10
A7: pac4cdiwpl11v | B7: Document Indexing Application | C7: =VLOOKUP(B7,CMDB_Apps!B:J,9,FALSE) -> CORAM-DIA | D7: Operational | E7: 46070.146 | G7: pac4cdiwpl11v.corp.cvscaremark.com | H7: Linux Red Hat | I7: PROD | J7: PROD | K7: Document Indexing Application | L7: 10.223.66.167 | M7: corp.cvscaremark.com | N7: global | O7: 8.10
A8: rac4sphfpl10v | B8: SPLUNK - NON PCI | C8: =VLOOKUP(B8,CMDB_Apps!B:J,9,FALSE) -> TSS-Ops-Support-Observability | D8: Operational | E8: 46070.142 | G8: rac4sphfpl10v.corp.cvscaremark.com | H8: Linux Red Hat | I8: PROD | J8: PROD | K8: SPLUNK - NON PCI | L8: 10.223.192.5 | M8: corp.cvscaremark.com | N8: global | O8: 8.10
A9: pac4vbrxdpl10v | B9: VBRX | C9: =VLOOKUP(B9,CMDB_Apps!B:J,9,FALSE) -> 0 | D9: Operational | E9: 46070.13 | G9: pac4vbrxdpl10v.corp.cvscaremark.com | H9: Linux Red Hat | I9: PROD | J9: PROD | K9: VBRX | L9: 10.175.175.196 | M9: corp.cvscaremark.com | N9: global | O9: 8.10
A10: pac4vbrxddl10v | B10: VBRX | C10: =VLOOKUP(B10,CMDB_Apps!B:J,9,FALSE) -> 0 | D10: Operational | E10: 46070.128 | G10: pac4vbrxddl10v.corp.cvscaremark.com | H10: Linux Red Hat | I10: DEV | J10: DEV1 | K10: VBRX | L10: 10.175.128.4 | M10: corp.cvscaremark.com | N10: global | O10: 8.10
A11: pac4vbrxdnl10v | B11: VBRX | C11: =VLOOKUP(B11,CMDB_Apps!B:J,9,FALSE) -> 0 | D11: Operational | E11: 46070.128 | G11: pac4vbrxdnl10v.corp.cvscaremark.com | H11: Linux Red Hat | I11: TEST | J11: UAT | K11: VBRX | L11: 10.175.128.5 | M11: corp.cvscaremark.com | N11: global | O11: 8.10
A12: rac2cdpapl1v | B12: Customer Data Platform (CDP) | C12: =VLOOKUP(B12,CMDB_Apps!B:J,9,FALSE) -> 0 | D12: Operational | E12: 46070.127 | G12: rac2cdpapl1v.corp.cvscaremark.com | H12: Linux Red Hat | I12: PROD | J12: PROD | K12: Customer Data Platform (CDP) | L12: 10.175.2.7 | M12: corp.cvscaremark.com | N12: global | O12: 7.9
A13: paz1micrpl18v | B13: MICROSTRATEGY - PBM | C13: =VLOOKUP(B13,CMDB_Apps!B:J,9,FALSE) -> 0 | D13: Operational | E13: 46070.067 | G13: paz1micrpl18v.corp.cvscaremark.com | H13: Linux Red Hat | I13: PROD | J13: PROD | K13: MICROSTRATEGY - PBM | L13: 10.217.188.122 | M13: corp.cvscaremark.com | N13: global | O13: 8.10
... A134: raz1rxfdpa50 | B134: ACQ2.0, RxConnect | C134: =VLOOKUP(B134,CMDB_Apps!B:J,9,FALSE) -> #N/A | D134: Operational | E134: 46070.044 | G134: raz1rxfdpa50.cvs.com | H134: AIX | I134: PROD | J134: PROD | K134: ACQ2.0, RxConnect | L134: 10.217.18.124 | M134: cvs.com | N134: global | O134: 7.2.0.0
A135: prdpps1a | B135: DISPENSING - PPS, DISPENSING - TRISTAR | C135: =VLOOKUP(B135,CMDB_Apps!B:J,9,FALSE) -> #N/A | D135: Operational | E135: 46069.957 | G135: prdpps1a.caremarkrx.net | H135: AIX | I135: PROD | J135: PROD | K135: DISPENSING - PPS, DISPENSING - TRISTAR | L135: 10.89.34.28 | N135: global | O135: 7.2.0.0
A136: prdpps1b | B136: DISPENSING - PPS | C136: =VLOOKUP(B136,CMDB_Apps!B:J,9,FALSE) -> PCW_IT_MailBackendDispensing_L2Support | D136: Operational | E136: 46069.956 | G136: prdpps1b.caremarkrx.net | H136: AIX | I136: PROD | J136: PROD | K136: DISPENSING - PPS | L136: 10.89.34.27 | N136: global | O136: 7.2.0.0
A137: prdtmq1a | B137: MAIL ORDER LETTERS AND FAXES, DISPENSING - TRISTAR, WEBSPHERE - MQ | C137: =VLOOKUP(B137,CMDB_Apps!B:J,9,FALSE) -> #N/A | D137: Operational | E137: 46069.956 | G137: prdtmq1a.caremarkrx.net | H137: AIX | I137: PROD | J137: PROD | K137: MAIL ORDER LETTERS AND FAXES, DISPENSING - TRISTAR, WEBSPHERE - MQ | L137: 10.89.34.22 | N137: global | O137: 7.2.0.0
A138: prdtdb1a | B138: DISPENSING - TRISTAR | C138: =VLOOKUP(B138,CMDB_Apps!B:J,9,FALSE) -> PCW_IT_MailBackendDispensing_L2Support | D138: Operational | E138: 46069.956 | G138: prdtdb1a.caremarkrx.net | H138: AIX | I138: PROD | J138: PROD | K138: DISPENSING - TRISTAR | L138: 10.89.34.24 | N138: global | O138: 7.2.0.0
A139: prdtmq1b | B139: WEBSPHERE - MQ, DISPENSING - TRISTAR | C139: =VLOOKUP(B139,CMDB_Apps!B:J,9,FALSE) -> #N/A | D139: Operational | E139: 46069.956 | G139: prdtmq1b.caremarkrx.net | H139: AIX | I139: PROD | J139: PROD | K139: WEBSPHERE - MQ, DISPENSING - TRISTAR | L139: 10.89.34.21 | N139: global | O139: 7.2.0.0
A140: wbpnim1 | B140: INFRASTRUCTURE UNIX TECH SERVICE, AIX - Solaris Nim-Jump Servers | C140: =VLOOKUP(B140,CMDB_Apps!B:J,9,FALSE) -> #N/A | D140: Operational | E140: 46069.956 | G140: wbpnim1.caremarkrx.net | H140: AIX | I140: TEST | J140: SANDBOX-TEST | K140: INFRASTRUCTURE UNIX TECH SERVICE, AIX - Solaris Nim-Jump Servers | L140: 10.89.34.18 | M140: none | N140: global | O140: 7.3.0.0
A141: pca1bcdbpl2v | B141: DISPENSING - SPECIALTY - PPS | C141: =VLOOKUP(B141,CMDB_Apps!B:J,9,FALSE) -> PCW_IT_SpecialtyBackendDispensing_L2Support | D141: Operational | E141: 46069.944 | G141: pca1bcdbpl2v.corp.cvscaremark.com | H141: Linux Red Hat | I141: PROD | J141: PROD | K141: DISPENSING - SPECIALTY - PPS | L141: 10.90.32.70 | M141: corp.cvscaremark.com | N141: global | O141: 7.9
A142: prdtrs2a | B142: DISPENSING - TRISTAR, MAIL ORDER LETTERS AND FAXES | C142: =VLOOKUP(B142,CMDB_Apps!B:J,9,FALSE) -> #N/A | D142: Operational | E142: 46069.931 | G142: prdtrs2a.caremarkrx.net | H142: AIX | I142: PROD | J142: PROD | K142: DISPENSING - TRISTAR, MAIL ORDER LETTERS AND FAXES | L142: 10.91.34.36 | M142: caremarkrx.net | N142: global | O142: 7.2.0.0
A143: prdpps2a | B143: DISPENSING - PPS, DISPENSING - TRISTAR | C143: =VLOOKUP(B143,CMDB_Apps!B:J,9,FALSE) -> #N/A | D143: Operational | E143: 46069.929 | G143: prdpps2a.caremarkrx.net | H143: AIX | I143: PROD | J143: PROD | K143: DISPENSING - PPS, DISPENSING - TRISTAR | L143: 10.91.34.18 | N143: global | O143: 7.2.0.0
A144: prdtdb2a | B144: DISPENSING - TRISTAR | C144: =VLOOKUP(B144,CMDB_Apps!B:J,9,FALSE) -> PCW_IT_MailBackendDispensing_L2Support | D144: Operational | E144: 46069.928 | G144: prdtdb2a.caremarkrx.net | H144: AIX | I144: PROD | J144: PROD | K144: DISPENSING - TRISTAR | L144: 10.91.34.21 | N144: global | O144: 7.2.0.0
A145: prdtmq2a | B145: MAIL ORDER LETTERS AND FAXES, DISPENSING - TRISTAR, WEBSPHERE - MQ | C145: =VLOOKUP(B145,CMDB_Apps!B:J,9,FALSE) -> #N/A | D145: Operational | E145: 46069.928 | G145: prdtmq2a.caremarkrx.net | H145: AIX | I145: PROD | J145: PROD | K145: MAIL ORDER LETTERS AND FAXES, DISPENSING - TRISTAR, WEBSPHERE - MQ | L145: 10.91.34.24 | N145: global | O145: 7.2.0.0
A146: prdtmq2b | B146: WEBSPHERE - MQ, DISPENSING - TRISTAR | C146: =VLOOKUP(B146,CMDB_Apps!B:J,9,FALSE) -> #N/A | D146: Operational | E146: 46069.928 | G146: prdtmq2b.caremarkrx.net | H146: AIX | I146: PROD | J146: PROD | K146: WEBSPHERE - MQ, DISPENSING - TRISTAR | L146: 10.91.34.25 | N146: global | O146: 7.2.0.0
A147: prdtdb2b | B147: DISPENSING - TRISTAR | C147: =VLOOKUP(B147,CMDB_Apps!B:J,9,FALSE) -> PCW_IT_MailBackendDispensing_L2Support | D147: Operational | E147: 46069.928 | G147: prdtdb2b.caremarkrx.net | H147: AIX | I147: PROD | J147: PROD | K147: DISPENSING - TRISTAR | L147: 10.91.34.22 | N147: global | O147: 7.2.0.0
A148: prdtrs2b | B148: DISPENSING - TRISTAR | C148: =VLOOKUP(B148,CMDB_Apps!B:J,9,FALSE) -> PCW_IT_MailBackendDispensing_L2Support | D148: Operational | E148: 46069.928 | G148: prdtrs2b.caremarkrx.net | H148: AIX | I148: PROD | J148: PROD | K148: DISPENSING - TRISTAR | L148: 10.91.34.28 | N148: global | O148: 7.2.0.0
A149: prdpps2b | B149: DISPENSING - PPS, DISPENSING - TRISTAR | C149: =VLOOKUP(B149,CMDB_Apps!B:J,9,FALSE) -> #N/A | D149: Operational | E149: 46069.928 | G149: prdpps2b.caremarkrx.net | H149: AIX | I149: PROD | J149: PROD | K149: DISPENSING - PPS, DISPENSING - TRISTAR | L149: 10.91.34.17 | N149: global | O149: 7.2.0.0
A150: chinim2 | B150: AIX - Solaris Nim-Jump Servers | C150: =VLOOKUP(B150,CMDB_Apps!B:J,9,FALSE) -> 0 | D150: Operational | E150: 46069.928 | G150: chinim2.caremarkrx.net | H150: AIX | I150: TEST | J150: SANDBOX-TEST | K150: AIX - Solaris Nim-Jump Servers | L150: 10.91.34.11 | M150: none | N150: global | O150: 7.3.0.0
A151: prdtbu2b | B151: EMC DATA PROTECTION ADVISOR, TIVOLI STORAGE MANAGER (TSM) | C151: =VLOOKUP(B151,CMDB_Apps!B:J,9,FALSE) -> #N/A | D151: Operational | E151: 46069.928 | G151: prdtbu2b.caremarkrx.net | H151: AIX | I151: PROD | J151: PROD | K151: EMC DATA PROTECTION ADVISOR, TIVOLI STORAGE MANAGER (TSM) | L151: 10.91.34.20 | N151: global | O151: 7.2.0.0
A152: paz1sppganl3v | B152: SpRx 2.0 | C152: =VLOOKUP(B152,CMDB_Apps!B:J,9,FALSE) -> SPRX 2.0 TIER 3 | D152: Operational | E152: 46069.925 | G152: paz1sppganl3v.corp.cvscaremark.com | H152: Linux Red Hat | I152: TEST | J152: PT | K152: SpRx 2.0 | L152: 10.9.80.102 | M152: corp.cvscaremark.com | N152: global | O152: 8.10
A153: paz1sppanl23v | B153: SpRx 2.0 | C153: =VLOOKUP(B153,CMDB_Apps!B:J,9,FALSE) -> SPRX 2.0 TIER 3 | D153: Operational | E153: 46069.925 | G153: paz1sppanl23v.corp.cvscaremark.com | H153: Linux Red Hat | I153: TEST | J153: PT | K153: SpRx 2.0 | L153: 10.9.80.106 | M153: corp.cvscaremark.com | N153: global | O153: 8.10
A154: paz1sppcnl11v | B154: SpRx 2.0 | C154: =VLOOKUP(B154,CMDB_Apps!B:J,9,FALSE) -> SPRX 2.0 TIER 3 | D154: Operational | E154: 46069.925 | G154: paz1sppcnl11v.corp.cvscaremark.com | H154: Linux Red Hat | I154: TEST | J154: PT | K154: SpRx 2.0 | L154: 10.9.62.221 | M154: corp.cvscaremark.com | N154: global | O154: 8.10
A155: paz1sppgnl11v | B155: SpRx 2.0 | C155: =VLOOKUP(B155,CMDB_Apps!B:J,9,FALSE) -> SPRX 2.0 TIER 3 | D155: Operational | E155: 46069.925 | G155: paz1sppgnl11v.corp.cvscaremark.com | H155: Linux Red Hat | I155: TEST | J155: PT | K155: SpRx 2.0 | L155: 10.9.62.216 | M155: corp.cvscaremark.com | N155: global | O155: 8.10
A156: raz1tvipa2 | B156: TIVOLI MONITOR 6 (ITM6) | C156: =VLOOKUP(B156,CMDB_Apps!B:J,9,FALSE) -> TSS-Ops-Support-Observability | D156: Operational | E156: 46069.925 | G156: raz1tvipa2.caremarkrx.net | H156: AIX | I156: PROD | J156: PROD | K156: TIVOLI MONITOR 6 (ITM6) | L156: 10.93.7.68 | M156: none | N156: global | O156: 7.2.0.0
A157: paz1sppanl12v | B157: SpRx 2.0 | C157: =VLOOKUP(B157,CMDB_Apps!B:J,9,FALSE) -> SPRX 2.0 TIER 3 | D157: Operational | E157: 46069.925 | G157: paz1sppanl12v.corp.cvscaremark.com | H157: Red Hat Enterprise Linux Release 8.10 (ootpa) | I157: TEST | J157: PT | K157: SpRx 2.0 | L157: 10.9.62.219 | M157: corp.cvscaremark.com | N157: global | O157: 8.10
A158: paz1sppanl13v | B158: SpRx 2.0 | C158: =VLOOKUP(B158,CMDB_Apps!B:J,9,FALSE) -> SPRX 2.0 TIER 3 | D158: Operational | E158: 46069.925 | G158: paz1sppanl13v.corp.cvscaremark.com | H158: Linux Red Hat | I158: TEST | J158: PT | K158: SpRx 2.0 | L158: 10.9.80.109 | M158: corp.cvscaremark.com | N158: global | O158: 8.10
A159: paz1sppanl16v | B159: SpRx 2.0 | C159: =VLOOKUP(B159,CMDB_Apps!B:J,9,FALSE) -> SPRX 2.0 TIER 3 | D159: Operational | E159: 46069.924 | G159: paz1sppanl16v.corp.cvscaremark.com | H159: Linux Red Hat | I159: TEST | J159: PT | K159: SpRx 2.0 | L159: 10.9.80.124 | M159: corp.cvscaremark.com | N159: global | O159: 8.10
A160: paz1sppanl14v | B160: SpRx 2.0 | C160: =VLOOKUP(B160,CMDB_Apps!B:J,9,FALSE) -> SPRX 2.0 TIER 3 | D160: Operational | E160: 46069.924 | G160: paz1sppanl14v.corp.cvscaremark.com | H160: Linux Red Hat | I160: TEST | J160: PT | K160: SpRx 2.0 | L160: 10.9.80.110 | M160: corp.cvscaremark.com | N160: global | O160: 8.10
...

Sheet CMDB_Apps
A1: Application ID | B1: Name | C1: Status | D1: Business criticality | E1: Business Unit | F1: Last updated by | G1: Business owner | H1: Operational Owner | I1: Technical Owner | J1: Support group | K1: Risk Tier | L1: Risk indicator | M1: Last change applied date | N1: Description | O1: Target Business Application | P1: Business process | Q1: Application type | R1: Architecture type | S1: Install type | T1: Life Cycle Stage Status | U1: Life Cycle Stage | V1: Technology stack | W1: User base | X1: Platform | Y1: Application Instance ID | Z1: Emergency tier | AA1: Data classification | AB1: Certified | AC1: Model ID
B2: myPBM GitHub Actions Pipeline | C2: Production | E2: PSS Pharmacy Service Segment | F2: system | G2: Dwarakanath Raghunathan | H2: Dwarakanath Raghunathan | I2: Richard Berktold | J2: myPBM_SRE | N2: Github Actions Build and Deploy Workflows implemented by the myPBM SRE team to replace existing Jenkins pipelines | Q2: Homegrown | S2: PaaS | AB2: FALSE | AC2: myPBM GitHub Actions Pipeline
A3: 2349 | B3: .Net Solutions | C3: Production | E3: HCB | F3: system | G3: Jinex Thomas Thandiakkal | H3: Jinex Thomas Thandiakkal | I3: Neeta Myageri | J3: L1.0-Framework Services Support | K3: Low Risk | N3: FS .NET products and solutions | Q3: Homegrown | S3: On Premise | Y3: OI-D52531D80E71457995771FE288B72A25 | AA3: Unclassified | AB3: FALSE | AC3: .Net Solutions
B4: 1E Platform | C4: Production | E4: ISTS | F4: system | G4: Joseph Lombardi | H4: Joseph Lombardi | I4: Sarah Thomas | K4: Low Risk | N4: Provides automated, real-time configuration to workstation clients. Provides client system details. Also used for Nomad single-site download information | Q4: COTS | S4: IaaS | AA4: Restricted | AB4: FALSE | AC4: 1E Platform
B5: 1E Shopping | C5: Production | E5: ISTS | F5: system | G5: Joseph Lombardi | H5: Joseph Lombardi | I5: Sarah Thomas | K5: Low Risk | N5: Shopping is used as a application ordering solution that can be itegrated with Service Now. It provides employees with an automated portal service that can fulfill requests for apps, new devices and equipment such as desks for home working or anything | Q5: COTS | S5: IaaS | AA5: Unclassified | AB5: FALSE | AC5: 1E Shopping
B6: 340B Data Products | C6: Production | F6: system | G6: Ryan Rowley | H6: Jose Vinay Chalissery | I6: Roshan Kumar | J6: 340B_Data_Products_change_mgnmt | K6: Low Risk | N6: Consolidated 340B data from the enterprise to enable reporting and ad hoc analyses related to the 340B program. | Q6: Homegrown | S6: Hybrid | AA6: Confidential | AB6: FALSE | AC6: 340B Data Products
B7: 340B Data Products Retail | C7: Production | E7: PSS Pharmacy Service Segment | F7: system | G7: Jose Vinay Chalissery | H7: Kamini Malhari Bokefode | I7: Aswani Gollakota | J7: three_forty_b_scheduling | N7: This is a set of Analytical engineering products created for 340 business for retail line of business. This includes products such as retail 340B feed, retail opportunity, retail outcomes etc. | Q7: COTS | S7: SaaS | AB7: FALSE | AC7: 340B Data Products Retail
B8: 340B Smart | C8: Production | E8: HCB | F8: system | G8: Darren West | H8: David Sterzel | I8: Micah Mcnelly | K8: High Risk | N8: 340b Smart Automatically splits and tracks replenishment orders for eligible medications into multiple accounts (340B, GPO, WAC.) | Q8: Homegrown | S8: IaaS | AA8: Confidential | AB8: FALSE | AC8: 340B Smart
A9: 2145 | B9: 3rd Party Feeder | C9: Production | E9: HCB | F9: system | G9: Alex Sawa | H9: Srideepthi Vejendla | I9: Viatcheslav Mironenko | J9: L1.0-SIMPLE STEPS APP SUPPORT | K9: Low Risk | N9: This is an application that is used by SimpleSteps to receive status about Miavita program completions and starts. This application also provides the Webservices for SSHL/PHR domain. | Q9: Homegrown | S9: On Premise | Y9: OI-D8506491C204445A9C3AEBB82361A2F6 | AA9: Confidential | AB9: FALSE | AC9: 3rd Party Feeder
B10: 90 DAY & MTM | C10: Production | E10: Retail | F10: system | G10: Lidia Thomas | H10: Lidia Thomas | I10: Alexander Sahakian | K10: Low Risk | N10: 90 Day Medication Therapy Management. RxDW provides 90 Day (Accept/Decline) Disposition details to RxConnect using 90-day(RxOutreach) application. | Q10: Homegrown | S10: Hybrid | AA10: Confidential | AB10: FALSE | AC10: 90 DAY & MTM
B11: A&BC Life Inusurance | C11: Production | E11: Corporate | F11: 2646189 | G11: Aamir Shibli | H11: Prabhu Ramakrishnan | I11: Prabhu Ramakrishnan | J11: EDML SRE Prod Support | N11: The A&BC data monetization and strategy team is bringing a product to market that will allow Life Insurance companies/brokers the ability to “ping” CVS Health with demographic information in order to receive back individual patient medical history; including but not limited to, health insurance claims/eligibility roster, Caremark PBM claims/eligibility roster, retail pharmacy dispensement, medical encounters at the MinuteClinic, etc. Our life insurance partners will be able to ‘ping’ the CVS data sources relative to their data needs. | Q11: Homegrown | S11: DaaS | AB11: FALSE | AC11: A&BC Life Inusurance
B12: A11Y Media | C12: Production | E12: SS Shared Services | F12: system | G12: Ryan Brady | H12: Matthew Ferrone | I12: Cory Joseph | J12: Corp-Digital-A11Y-L2 Support | N12: Use of GCP AI Vertex Media Studio to create internal marketing and educational videos for designers and engineers. | Q12: COTS | S12: SaaS | AB12: FALSE | AC12: A11Y Media
B13: A1A_Reporting | C13: Production | E13: HCB | F13: system | G13: Teresa Mitchelson | H13: Joseph Leathlean | I13: Joseph Leathlean | K13: Low Risk | N13: A1A Reporting | Q13: COTS | S13: Hybrid | AA13: Restricted | AB13: FALSE | AC13: A1A_Reporting
B14: A4LEvents | C14: Production | E14: Health Care Benefits | F14: system | G14: Ellen Chamberlain | H14: Krishna Pyneni | I14: Shrivallabha Deshpande | K14: Low Risk | N14: This component will process member events emitted by Enterprise Patient Hub (EPH) to keep ACCOUNT FOR LIFE table updated with latest information. | Q14: Homegrown | S14: On Premise | AA14: Proprietary | AB14: FALSE | AC14: A4LEvents
A15: 4209 | B15: AAD Application proxy | C15: Production | E15: ISTS | F15: system | G15: Eric Kovacs | H15: Anthony Vasi | I15: Gregory Nichols | K15: Low Risk | N15: Azure AD Application Proxy provides a simple, secure, and cost-effective remote access solution to all your on-premises applications. | Q15: COTS | S15: On Premise | Y15: OI-E3EFEF2FEE8340858DC14B4D5FEAF101 | AA15: Unclassified | AB15: FALSE | AC15: AAD Application proxy
B16: AAP-HCB-POA-COB-ANALYTICS | C16: Production | E16: HCB | F16: system | G16: Patricia Serio | H16: Narayan Sahasranamaiyer | I16: Kuntal Ghosh | J16: Claims Analytics Data Engineering | N16: Coordination of Benefits (COB) is to determine the correct order of benefits for members with coverage on multiple insurance plans across Commercial ,Medicare and Medicaid LOBs | Q16: Homegrown | S16: PaaS | AB16: FALSE | AC16: AAP-HCB-POA-COB-ANALYTICS
B17: AAP-HCB-POA-FWA-ANALYTICS | C17: Production | E17: HCB | F17: system | G17: Patricia Serio | H17: Seema Yadav | I17: Kuntal Ghosh | J17: Claims Analytics Data Engineering | N17: FWA: Program to detect Provider fraud waste and abuse. like provider billing for services never rendered or misrepresenting a patient's condition to get payment. Over-utilization of services, such as using more expensive treatments or tests than necessary. Excessive charging or incorrect billing. | Q17: Homegrown | S17: PaaS | AB17: FALSE | AC17: AAP-HCB-POA-FWA-ANALYTICS
A18: 2483 | B18: AAS Billing/AR | C18: Production | E18: HCB | F18: 2638821 | G18: Darlene Malenfant | H18: Mario Quiroga | I18: David Stiano | J18: L1.0-KB AAS APP SUPPORT | K18: Medium Risk | N18: Supports legacy Billing and remittance for fully insured customers. | Q18: Homegrown | S18: On Premise | Y18: OI-6D718BA78F1D4069ADD781D2F43F536B | AA18: Restricted | AB18: FALSE | AC18: AAS Billing/AR
B19: AAS Product Screen Tool | C19: Production | E19: HCB | F19: system | G19: Kelly McClellan | H19: April Isenberg | I19: Christopher Loughlin | J19: L1.0-KB AAS APP SUPPORT | K19: Low Risk | N19: Service Plan Sponsors | Q19: Homegrown | S19: On Premise | AA19: Unclassified | AB19: FALSE | AC19: AAS Product Screen Tool
B20: Ab Initio Aetna | C20: Production | E20: HCB | F20: 9857522 | G20: Jason Ricapito | H20: Kurt Holever | I20: Kurt Holever | J20: HCB-IT-Ab Initio HCB-L2 Technical Support | K20: Low Risk | N20: Ab Initio provides the most powerful data processing platform available. It can process complex enterprise data using sophisticated business logic at any scale. The applications are built graphically and can run within a batch, streaming, in-memory, or microservice architecture. High performance, end-to-end applications run in parallel and are distributed across containers or networks of different servers. It supports distributed checkpoint restart with application monitoring and alerting. At runtime, the platform adapts to changes in the data formats, rules, and infrastructure, providing a new level of agility. | Q20: COTS | S20: IaaS | AA20: Unclassified | AB20: FALSE | AC20: Ab Initio Aetna
B21: ABBYY FineReader PDF | C21: Production | E21: ISTS | F21: system | G21: Sarah Thomas | H21: David Ottavi | I21: David Ottavi | J21: Desktop Support | K21: Low Risk | N21: Abbyy Fine Reader is an OCR (Optical Character Recognition) application primarily used to edit incoming provider fax on patient information and is replacing another Microsoft OCR product (MODI) | Q21: COTS | S21: On Premise | AA21: Unclassified | AB21: FALSE | AC21: ABBYY FineReader PDF
B22: ABC CADL GWTH Analytics | C22: Production | E22: HCB | F22: 2646189 | G22: Fabio Casadio | H22: Frederick Kirwin | I22: Frederick Kirwin | K22: Low Risk | N22: This application supports exploratory data science work within A&BC, under the Care Delivery and Growth Analytics vertical. | Q22: Homegrown | S22: IaaS | AA22: Confidential | AB22: FALSE | AC22: ABC CADL GWTH Analytics
B23: ABC CDA MC Data Science | C23: Production | E23: HCB | F23: 2646189 | G23: Fabio Casadio | H23: Frederick Kirwin | I23: Frederick Kirwin | K23: Medium Risk | N23: This application supports exploratory data science work within A&BC, under the Clinical Delivery Analytics vertical. | Q23: Homegrown | S23: IaaS | AA23: Restricted | AB23: FALSE | AC23: ABC CDA MC Data Science
B24: ABC PSS Product Data Engineering | C24: Production | E24: PBM (Segment) | F24: 2273613 | G24: Joshua Fredell | H24: Ramchandra Reddy Rupireddy | I24: Ramchandra Reddy Rupireddy | J24: PBM-ABC-Data Engineering-L2 Support | K24: Low Risk | N24: Pharmacy benefits management data engineering application to maintain various semantic data layers required for analytics, operations, and reporting. The application also includes certain medical data such as Prior Authorization. | Q24: Homegrown | S24: IaaS | AA24: Confidential | AB24: FALSE | AC24: ABC PSS Product Data Engineering
B25: ABERateComparisonAPI | C25: Production | E25: HCB | F25: 2646189 | G25: William Bryant | H25: Cecily Santolini | I25: Arockiaswamy Arulraj | K25: Low Risk | N25: REST API to get response back from ABE system for the plan recommendation based on the request submitted from SMART | Q25: Homegrown | S25: PaaS | AA25: Unclassified | AB25: FALSE | AC25: ABERateComparisonAPI
B26: ABHKY_Informatics_Process_Control | C26: Production | E26: HCB | F26: 9857522 | G26: Erin Hall | H26: Erin Hall | I26: Blake Wagner | N26: SQL Server Integration Services (SSIS .dtsx) package utilized by Aetna Better Health of Kentucky Informatics developers to automate data loads and reports | Q26: Homegrown | S26: On Premise | AB26: FALSE | AC26: ABHKY_Informatics_Process_Control
B27: ACA EDGE Data Submission | C27: Production | E27: HCB | F27: system | G27: Errin Crowell | H27: Amee Parikh | I27: Claudia Sophie Israel | K27: Medium Risk | N27: The Application submits IFP and SG Member and Claims data to the EDGE servers for ACA Risk Adjustment. | Q27: Homegrown | S27: On Premise | AA27: Restricted | AB27: FALSE | AC27: ACA EDGE Data Submission
A28: 2039 | B28: ACAS - Automatic Letter Generator | C28: Production | E28: HCB | F28: system | G28: Margaret Barnes | H28: Chris Pierce | I28: Michael Sankner | J28: L1.0-DESKTOP APP SUPPORT | K28: Low Risk | N28: VB application that creates and maintains letters that are sent to Providers and Members. Information is Approved within this application the information will be accessible by ACAS claim processors on the mainframe. This application internally maintains versions of each letter template. | Q28: Homegrown | S28: On Premise | Y28: OI-EF57B37AB0CD4E50A44DF6493FE2291C | AA28: Unclassified | AB28: FALSE | AC28: ACAS - Automatic Letter Generator
A29: 2043 | B29: ACAS - CDL LCI | C29: Production | E29: HCB | F29: system | G29: Elizabeth Chittenden | H29: Ross Labranche | I29: Michael Sankner | J29: L1.0-DESKTOP APP SUPPORT | K29: Low Risk | N29: Desktop application used to maintain : State Rules for Claim Delay Letter Generation, State Rules for Late Claim Interest Calculation and State Conditions for Late Claim Interest Calculation. | Q29: Homegrown | S29: On Premise | Y29: OI-82350A55D4F448599148AC08715871DE | AA29: Unclassified | AB29: FALSE | AC29: ACAS - CDL LCI
A30: 1904 | B30: ACAS Conversion Control Tool | C30: Production | E30: HCB | F30: system | G30: Dorene Ciarcia | H30: Annette Cochran | I30: Michael Sankner | J30: L1.0-DESKTOP APP SUPPORT | K30: Low Risk | N30: Allows business to enter Control Number, Office Key combinations which are used to hold and release claims for new business testing and financial fixes | Q30: Homegrown | S30: On Premise | Y30: OI-2986F5D585E94423A3AAE6BC2C3B1F73 | AA30: Unclassified | AB30: FALSE | AC30: ACAS Conversion Control Tool
A31: 1609 | B31: ACAS Draft Accounting Assignment Tool | C31: Production | E31: HCB | F31: system | G31: Frank Echanique | H31: Jeffry Agnew | I31: Michael Sankner | J31: L1.0-DESKTOP APP SUPPORT | K31: Low Risk | N31: Allows the business to update/maintain the ACAS Bank Account table. | Q31: Homegrown | S31: On Premise | Y31: OI-41825E27C3DA4F5C94BC880BD865121F | AA31: Unclassified | AB31: FALSE | AC31: ACAS Draft Accounting Assignment Tool
B32: ACAS History Reconstruction Tool | C32: Production | E32: HCB | F32: system | G32: Holly Allen | H32: Holly Allen | I32: Adam Kelley | K32: Low Risk | N32: The ACAS History Reconstruction Tool gathers financial and diagnostic information for an individual from the ACAS claim history screens and allows the user to export the data into an Excel spreadsheet. This is useful for file audits, diagnostic trending, and discovering where financial errors may have occurred on a member file. | Q32: Homegrown | S32: On Premise | AA32: Confidential | AB32: FALSE | AC32: ACAS History Reconstruction Tool
B33: ACAS PL EX LookUp | C33: Production | E33: HCB | F33: system | G33: Holly Allen | H33: Holly Allen | I33: Adam Kelley | K33: Low Risk | N33: Application scrapes data from the PL screen in ACAS and then uses that data to scrape from the LA, LI, and/or LK screens to display all scraped in one output. | Q33: Homegrown | S33: On Premise | AA33: Confidential | AB33: FALSE | AC33: ACAS PL EX LookUp
B34: ACC COLLEAGUE TRACK DASHBOARD | C34: Production | E34: Health Care Delivery (HCD) | F34: 2585725 | G34: Kirk Widner | H34: Kirk Widner | I34: Shashwati Ganguly | K34: Low Risk | N34: ACCCOLLEAGUETRACKDB ACC COLLEAGUE TRACK DASHBOARD | Q34: Hybrid | S34: Hybrid | AA34: Confidential | AB34: FALSE | AC34: ACC COLLEAGUE TRACK DASHBOARD
B35: ACCAT (Aetna Claim/Call Analytics Tool) | C35: Production | E35: HCB | F35: system | G35: Elizabeth Linthicum | H35: Kiran Nair | I35: Harisha Reddiboina | J35: Aetna Data Lake Operational Data Store_ADL-ODS | K35: Medium Risk | N35: Calculate first call and first claim resolution based on documentation in ASD/GPS (call) and ACAS (claim) | Q35: Homegrown | S35: IaaS | AA35: Restricted | AB35: FALSE | AC35: ACCAT (Aetna Claim/Call Analytics Tool)
A36: 2463 | B36: Accelerate | C36: Production | E36: ISTS | F36: system | G36: Jay Zirblis | H36: Jay Zirblis | I36: Jay Zirblis | K36: Low Risk | N36: This is a SQL database containing all applications installed on clients at Aetna. 9 data sources currently feed the database including the application inventory. The primary purpose of this system is to play and automate desktop lease replacements and upgrades. | Q36: Homegrown | S36: On Premise | Y36: OI-6F65CBF6B8594E28BA49C83BE50F0B93 | AA36: Confidential | AB36: FALSE | AC36: Accelerate
B37: Access Hub | C37: Production | E37: HCB | F37: system | G37: Lorraine Lord | H37: Claire Jost | I37: Komal Satpathy | J37: Aetna Employer Portal_Assignment_group | N37: A new portal to register and provision users for Plan Sponsor applications with latest tech for better user experience. It replaces existing PSREG application. | Q37: Homegrown | S37: PaaS | AB37: FALSE | AC37: Access Hub
B38: accesscontrolservice | C38: Production | E38: HCB | F38: system | G38: Jinex Thomas Thandiakkal | H38: Jinex Thomas Thandiakkal | I38: Neeta Myageri | J38: L1.0-Framework Services Support | K38: Low Risk | N38: Accesscontrol service is used to update/retrieve the user staus. | Q38: Homegrown | S38: Hybrid | AA38: Unclassified | AB38: FALSE | AC38: accesscontrolservice
A39: 4404 | B39: AccessNow | C39: Production | E39: Corporate | F39: system | G39: Subhashini Natarajan | H39: Subhashini Natarajan | I39: Subhashini Natarajan | K39: High Risk | N39: AccessNow supports the following security business function from, to and for cloud environments: Access Request Access Approval and workflow management Access provisioning Account registration/setup Access Deprovisioning | Q39: COTS | S39: SaaS | Y39: OI-29DA7C4BFB844651AD8510B966424738 | AA39: Restricted | AB39: FALSE | AC39: AccessNow
B40: AccessNow-CVS | C40: Production | E40: Corporate | F40: system | G40: Subhashini Natarajan | H40: Victoria Oravits | I40: Subhashini Natarajan | J40: Self-service Access Request - AccessNow | K40: High Risk | N40: Cloud-based SaaS application supporting the Identity and Access Management (IAM) Provisioning Consolidation. Replaces the Oracle Identity Manager (OIM) system. | Q40: COTS | S40: Hybrid | AA40: Restricted | AB40: FALSE | AC40: AccessNow-CVS
...
